<?xml version="1.0" encoding="utf-8"?>
<test-run id="0" testcasecount="12" result="Failed" total="12" passed="0" failed="12" inconclusive="0" skipped="0" asserts="2" portable-engine-version="3.3.0.0" start-time="2016-09-30 18:25:02Z" end-time="2016-09-30 18:25:05Z" duration="2.846905">
  <test-suite type="Assembly" id="1021" name="tests, Version=1.0.0.0, Culture=neutral, PublicKeyToken=null" fullname="tests, Version=1.0.0.0, Culture=neutral, PublicKeyToken=null" runstate="Runnable" testcasecount="12" result="Failed" site="Child" start-time="2016-09-30 18:25:02Z" end-time="2016-09-30 18:25:05Z" duration="2.664012" total="12" passed="0" failed="12" inconclusive="0" skipped="0" asserts="2">
    <settings>
      <setting name="WorkDirectory" value="E:\Projects\EthereumApiDotNetCore\tests" />
    </settings>
    <properties>
      <property name="ParallelScope" value="None" />
    </properties>
    <failure>
      <message><![CDATA[One or more child tests had errors]]></message>
    </failure>
    <test-suite type="SetUpFixture" id="1000" name="Tests" fullname="Tests.Config" classname="Tests.Config" runstate="Runnable" testcasecount="12" result="Failed" site="SetUp" start-time="2016-09-30 18:25:02Z" end-time="2016-09-30 18:25:05Z" duration="2.648203" total="12" passed="0" failed="12" inconclusive="0" skipped="0" asserts="2">
      <failure>
        <message><![CDATA[  Please, run ethereum node (geth.exe)
  Expected: No Exception to be thrown
  But was:  <EdjCase.JsonRpc.Client.RpcClientUnknownException: Error occurred when trying to send rpc requests(s) ---> System.Net.Http.HttpRequestException: An error occurred while sending the request. ---> System.Net.Http.WinHttpException: Не удается установить соединение с сервером
   at System.Runtime.CompilerServices.TaskAwaiter.ThrowForNonSuccess(Task task)
   at System.Runtime.CompilerServices.TaskAwaiter.HandleNonSuccessAndDebuggerNotification(Task task)
   at System.Runtime.CompilerServices.ConfiguredTaskAwaitable`1.ConfiguredTaskAwaiter.GetResult()
   at System.Net.Http.WinHttpHandler.<StartRequest>d__101.MoveNext()
   --- End of inner exception stack trace ---
   at System.Runtime.CompilerServices.TaskAwaiter.ThrowForNonSuccess(Task task)
   at System.Runtime.CompilerServices.TaskAwaiter.HandleNonSuccessAndDebuggerNotification(Task task)
   at System.Runtime.CompilerServices.ConfiguredTaskAwaitable`1.ConfiguredTaskAwaiter.GetResult()
   at System.Net.Http.HttpClient.<FinishSendAsync>d__58.MoveNext()
--- End of stack trace from previous location where exception was thrown ---
   at System.Runtime.CompilerServices.TaskAwaiter.ThrowForNonSuccess(Task task)
   at System.Runtime.CompilerServices.TaskAwaiter.HandleNonSuccessAndDebuggerNotification(Task task)
   at EdjCase.JsonRpc.Client.RpcClient.<SendAsync>d__23`2.MoveNext()
   --- End of inner exception stack trace ---
   at EdjCase.JsonRpc.Client.RpcClient.<SendAsync>d__23`2.MoveNext()
--- End of stack trace from previous location where exception was thrown ---
   at System.Runtime.CompilerServices.TaskAwaiter.ThrowForNonSuccess(Task task)
   at System.Runtime.CompilerServices.TaskAwaiter.HandleNonSuccessAndDebuggerNotification(Task task)
   at EdjCase.JsonRpc.Client.RpcClient.<SendRequestAsync>d__20.MoveNext()
--- End of stack trace from previous location where exception was thrown ---
   at System.Runtime.CompilerServices.TaskAwaiter.ThrowForNonSuccess(Task task)
   at System.Runtime.CompilerServices.TaskAwaiter.HandleNonSuccessAndDebuggerNotification(Task task)
   at System.Runtime.CompilerServices.ConfiguredTaskAwaitable`1.ConfiguredTaskAwaiter.GetResult()
   at Nethereum.JsonRpc.Client.RpcRequestResponseHandlerNoParam`1.<SendRequestAsync>d__7.MoveNext()
--- End of stack trace from previous location where exception was thrown ---
   at System.Runtime.CompilerServices.TaskAwaiter.ThrowForNonSuccess(Task task)
   at System.Runtime.CompilerServices.TaskAwaiter.HandleNonSuccessAndDebuggerNotification(Task task)
   at System.Runtime.CompilerServices.TaskAwaiter`1.GetResult()
   at Services.ContractService.<GetCurrentBlock>d__9.MoveNext() in E:\Projects\EthereumApiDotNetCore\src\Services\ContractService.cs:line 179
--- End of stack trace from previous location where exception was thrown ---
   at NUnit.Framework.Internal.ExceptionHelper.Rethrow(Exception exception)
   at NUnit.Framework.Internal.AsyncInvocationRegion.AsyncTaskInvocationRegion.WaitForPendingOperationsToComplete(Object invocationResult)
   at NUnit.Framework.Constraints.ThrowsConstraint.ExceptionInterceptor.Intercept(Object invocation)>
]]></message>
        <stack-trace><![CDATA[at Tests.Config.Initialize() in E:\Projects\EthereumApiDotNetCore\tests\Config.cs:line 58
]]></stack-trace>
      </failure>
      <test-suite type="TestFixture" id="1001" name="ContractQueueServiceTests" fullname="Tests.ContractQueueServiceTests" classname="Tests.ContractQueueServiceTests" runstate="Runnable" testcasecount="2" result="Failed" site="Parent" start-time="0001-01-01 00:00:00Z" end-time="0001-01-01 00:00:00Z" duration="0.000000" total="0" passed="0" failed="0" inconclusive="0" skipped="0" asserts="0">
        <failure>
          <message><![CDATA[OneTimeSetUp:   Please, run ethereum node (geth.exe)
  Expected: No Exception to be thrown
  But was:  <EdjCase.JsonRpc.Client.RpcClientUnknownException: Error occurred when trying to send rpc requests(s) ---> System.Net.Http.HttpRequestException: An error occurred while sending the request. ---> System.Net.Http.WinHttpException: Не удается установить соединение с сервером
   at System.Runtime.CompilerServices.TaskAwaiter.ThrowForNonSuccess(Task task)
   at System.Runtime.CompilerServices.TaskAwaiter.HandleNonSuccessAndDebuggerNotification(Task task)
   at System.Runtime.CompilerServices.ConfiguredTaskAwaitable`1.ConfiguredTaskAwaiter.GetResult()
   at System.Net.Http.WinHttpHandler.<StartRequest>d__101.MoveNext()
   --- End of inner exception stack trace ---
   at System.Runtime.CompilerServices.TaskAwaiter.ThrowForNonSuccess(Task task)
   at System.Runtime.CompilerServices.TaskAwaiter.HandleNonSuccessAndDebuggerNotification(Task task)
   at System.Runtime.CompilerServices.ConfiguredTaskAwaitable`1.ConfiguredTaskAwaiter.GetResult()
   at System.Net.Http.HttpClient.<FinishSendAsync>d__58.MoveNext()
--- End of stack trace from previous location where exception was thrown ---
   at System.Runtime.CompilerServices.TaskAwaiter.ThrowForNonSuccess(Task task)
   at System.Runtime.CompilerServices.TaskAwaiter.HandleNonSuccessAndDebuggerNotification(Task task)
   at EdjCase.JsonRpc.Client.RpcClient.<SendAsync>d__23`2.MoveNext()
   --- End of inner exception stack trace ---
   at EdjCase.JsonRpc.Client.RpcClient.<SendAsync>d__23`2.MoveNext()
--- End of stack trace from previous location where exception was thrown ---
   at System.Runtime.CompilerServices.TaskAwaiter.ThrowForNonSuccess(Task task)
   at System.Runtime.CompilerServices.TaskAwaiter.HandleNonSuccessAndDebuggerNotification(Task task)
   at EdjCase.JsonRpc.Client.RpcClient.<SendRequestAsync>d__20.MoveNext()
--- End of stack trace from previous location where exception was thrown ---
   at System.Runtime.CompilerServices.TaskAwaiter.ThrowForNonSuccess(Task task)
   at System.Runtime.CompilerServices.TaskAwaiter.HandleNonSuccessAndDebuggerNotification(Task task)
   at System.Runtime.CompilerServices.ConfiguredTaskAwaitable`1.ConfiguredTaskAwaiter.GetResult()
   at Nethereum.JsonRpc.Client.RpcRequestResponseHandlerNoParam`1.<SendRequestAsync>d__7.MoveNext()
--- End of stack trace from previous location where exception was thrown ---
   at System.Runtime.CompilerServices.TaskAwaiter.ThrowForNonSuccess(Task task)
   at System.Runtime.CompilerServices.TaskAwaiter.HandleNonSuccessAndDebuggerNotification(Task task)
   at System.Runtime.CompilerServices.TaskAwaiter`1.GetResult()
   at Services.ContractService.<GetCurrentBlock>d__9.MoveNext() in E:\Projects\EthereumApiDotNetCore\src\Services\ContractService.cs:line 179
--- End of stack trace from previous location where exception was thrown ---
   at NUnit.Framework.Internal.ExceptionHelper.Rethrow(Exception exception)
   at NUnit.Framework.Internal.AsyncInvocationRegion.AsyncTaskInvocationRegion.WaitForPendingOperationsToComplete(Object invocationResult)
   at NUnit.Framework.Constraints.ThrowsConstraint.ExceptionInterceptor.Intercept(Object invocation)>
]]></message>
        </failure>
      </test-suite>
      <test-case id="1002" name="TestPushAndGetContract" fullname="Tests.ContractQueueServiceTests.TestPushAndGetContract" methodname="TestPushAndGetContract" classname="Tests.ContractQueueServiceTests" runstate="Runnable" seed="2145919360" result="Failed" site="Parent" start-time="0001-01-01 00:00:00Z" end-time="0001-01-01 00:00:00Z" duration="0.000000" asserts="0">
        <failure>
          <message><![CDATA[OneTimeSetUp:   Please, run ethereum node (geth.exe)
  Expected: No Exception to be thrown
  But was:  <EdjCase.JsonRpc.Client.RpcClientUnknownException: Error occurred when trying to send rpc requests(s) ---> System.Net.Http.HttpRequestException: An error occurred while sending the request. ---> System.Net.Http.WinHttpException: Не удается установить соединение с сервером
   at System.Runtime.CompilerServices.TaskAwaiter.ThrowForNonSuccess(Task task)
   at System.Runtime.CompilerServices.TaskAwaiter.HandleNonSuccessAndDebuggerNotification(Task task)
   at System.Runtime.CompilerServices.ConfiguredTaskAwaitable`1.ConfiguredTaskAwaiter.GetResult()
   at System.Net.Http.WinHttpHandler.<StartRequest>d__101.MoveNext()
   --- End of inner exception stack trace ---
   at System.Runtime.CompilerServices.TaskAwaiter.ThrowForNonSuccess(Task task)
   at System.Runtime.CompilerServices.TaskAwaiter.HandleNonSuccessAndDebuggerNotification(Task task)
   at System.Runtime.CompilerServices.ConfiguredTaskAwaitable`1.ConfiguredTaskAwaiter.GetResult()
   at System.Net.Http.HttpClient.<FinishSendAsync>d__58.MoveNext()
--- End of stack trace from previous location where exception was thrown ---
   at System.Runtime.CompilerServices.TaskAwaiter.ThrowForNonSuccess(Task task)
   at System.Runtime.CompilerServices.TaskAwaiter.HandleNonSuccessAndDebuggerNotification(Task task)
   at EdjCase.JsonRpc.Client.RpcClient.<SendAsync>d__23`2.MoveNext()
   --- End of inner exception stack trace ---
   at EdjCase.JsonRpc.Client.RpcClient.<SendAsync>d__23`2.MoveNext()
--- End of stack trace from previous location where exception was thrown ---
   at System.Runtime.CompilerServices.TaskAwaiter.ThrowForNonSuccess(Task task)
   at System.Runtime.CompilerServices.TaskAwaiter.HandleNonSuccessAndDebuggerNotification(Task task)
   at EdjCase.JsonRpc.Client.RpcClient.<SendRequestAsync>d__20.MoveNext()
--- End of stack trace from previous location where exception was thrown ---
   at System.Runtime.CompilerServices.TaskAwaiter.ThrowForNonSuccess(Task task)
   at System.Runtime.CompilerServices.TaskAwaiter.HandleNonSuccessAndDebuggerNotification(Task task)
   at System.Runtime.CompilerServices.ConfiguredTaskAwaitable`1.ConfiguredTaskAwaiter.GetResult()
   at Nethereum.JsonRpc.Client.RpcRequestResponseHandlerNoParam`1.<SendRequestAsync>d__7.MoveNext()
--- End of stack trace from previous location where exception was thrown ---
   at System.Runtime.CompilerServices.TaskAwaiter.ThrowForNonSuccess(Task task)
   at System.Runtime.CompilerServices.TaskAwaiter.HandleNonSuccessAndDebuggerNotification(Task task)
   at System.Runtime.CompilerServices.TaskAwaiter`1.GetResult()
   at Services.ContractService.<GetCurrentBlock>d__9.MoveNext() in E:\Projects\EthereumApiDotNetCore\src\Services\ContractService.cs:line 179
--- End of stack trace from previous location where exception was thrown ---
   at NUnit.Framework.Internal.ExceptionHelper.Rethrow(Exception exception)
   at NUnit.Framework.Internal.AsyncInvocationRegion.AsyncTaskInvocationRegion.WaitForPendingOperationsToComplete(Object invocationResult)
   at NUnit.Framework.Constraints.ThrowsConstraint.ExceptionInterceptor.Intercept(Object invocation)>
]]></message>
        </failure>
      </test-case>
      <test-case id="1003" name="TestSaveUserContract" fullname="Tests.ContractQueueServiceTests.TestSaveUserContract" methodname="TestSaveUserContract" classname="Tests.ContractQueueServiceTests" runstate="Runnable" seed="733171015" result="Failed" site="Parent" start-time="0001-01-01 00:00:00Z" end-time="0001-01-01 00:00:00Z" duration="0.000000" asserts="0">
        <failure>
          <message><![CDATA[OneTimeSetUp:   Please, run ethereum node (geth.exe)
  Expected: No Exception to be thrown
  But was:  <EdjCase.JsonRpc.Client.RpcClientUnknownException: Error occurred when trying to send rpc requests(s) ---> System.Net.Http.HttpRequestException: An error occurred while sending the request. ---> System.Net.Http.WinHttpException: Не удается установить соединение с сервером
   at System.Runtime.CompilerServices.TaskAwaiter.ThrowForNonSuccess(Task task)
   at System.Runtime.CompilerServices.TaskAwaiter.HandleNonSuccessAndDebuggerNotification(Task task)
   at System.Runtime.CompilerServices.ConfiguredTaskAwaitable`1.ConfiguredTaskAwaiter.GetResult()
   at System.Net.Http.WinHttpHandler.<StartRequest>d__101.MoveNext()
   --- End of inner exception stack trace ---
   at System.Runtime.CompilerServices.TaskAwaiter.ThrowForNonSuccess(Task task)
   at System.Runtime.CompilerServices.TaskAwaiter.HandleNonSuccessAndDebuggerNotification(Task task)
   at System.Runtime.CompilerServices.ConfiguredTaskAwaitable`1.ConfiguredTaskAwaiter.GetResult()
   at System.Net.Http.HttpClient.<FinishSendAsync>d__58.MoveNext()
--- End of stack trace from previous location where exception was thrown ---
   at System.Runtime.CompilerServices.TaskAwaiter.ThrowForNonSuccess(Task task)
   at System.Runtime.CompilerServices.TaskAwaiter.HandleNonSuccessAndDebuggerNotification(Task task)
   at EdjCase.JsonRpc.Client.RpcClient.<SendAsync>d__23`2.MoveNext()
   --- End of inner exception stack trace ---
   at EdjCase.JsonRpc.Client.RpcClient.<SendAsync>d__23`2.MoveNext()
--- End of stack trace from previous location where exception was thrown ---
   at System.Runtime.CompilerServices.TaskAwaiter.ThrowForNonSuccess(Task task)
   at System.Runtime.CompilerServices.TaskAwaiter.HandleNonSuccessAndDebuggerNotification(Task task)
   at EdjCase.JsonRpc.Client.RpcClient.<SendRequestAsync>d__20.MoveNext()
--- End of stack trace from previous location where exception was thrown ---
   at System.Runtime.CompilerServices.TaskAwaiter.ThrowForNonSuccess(Task task)
   at System.Runtime.CompilerServices.TaskAwaiter.HandleNonSuccessAndDebuggerNotification(Task task)
   at System.Runtime.CompilerServices.ConfiguredTaskAwaitable`1.ConfiguredTaskAwaiter.GetResult()
   at Nethereum.JsonRpc.Client.RpcRequestResponseHandlerNoParam`1.<SendRequestAsync>d__7.MoveNext()
--- End of stack trace from previous location where exception was thrown ---
   at System.Runtime.CompilerServices.TaskAwaiter.ThrowForNonSuccess(Task task)
   at System.Runtime.CompilerServices.TaskAwaiter.HandleNonSuccessAndDebuggerNotification(Task task)
   at System.Runtime.CompilerServices.TaskAwaiter`1.GetResult()
   at Services.ContractService.<GetCurrentBlock>d__9.MoveNext() in E:\Projects\EthereumApiDotNetCore\src\Services\ContractService.cs:line 179
--- End of stack trace from previous location where exception was thrown ---
   at NUnit.Framework.Internal.ExceptionHelper.Rethrow(Exception exception)
   at NUnit.Framework.Internal.AsyncInvocationRegion.AsyncTaskInvocationRegion.WaitForPendingOperationsToComplete(Object invocationResult)
   at NUnit.Framework.Constraints.ThrowsConstraint.ExceptionInterceptor.Intercept(Object invocation)>
]]></message>
        </failure>
      </test-case>
      <test-suite type="TestFixture" id="1004" name="EthereumQueueOutTests" fullname="Tests.EthereumQueueOutTests" classname="Tests.EthereumQueueOutTests" runstate="Runnable" testcasecount="1" result="Failed" site="Parent" start-time="0001-01-01 00:00:00Z" end-time="0001-01-01 00:00:00Z" duration="0.000000" total="0" passed="0" failed="0" inconclusive="0" skipped="0" asserts="0">
        <failure>
          <message><![CDATA[OneTimeSetUp:   Please, run ethereum node (geth.exe)
  Expected: No Exception to be thrown
  But was:  <EdjCase.JsonRpc.Client.RpcClientUnknownException: Error occurred when trying to send rpc requests(s) ---> System.Net.Http.HttpRequestException: An error occurred while sending the request. ---> System.Net.Http.WinHttpException: Не удается установить соединение с сервером
   at System.Runtime.CompilerServices.TaskAwaiter.ThrowForNonSuccess(Task task)
   at System.Runtime.CompilerServices.TaskAwaiter.HandleNonSuccessAndDebuggerNotification(Task task)
   at System.Runtime.CompilerServices.ConfiguredTaskAwaitable`1.ConfiguredTaskAwaiter.GetResult()
   at System.Net.Http.WinHttpHandler.<StartRequest>d__101.MoveNext()
   --- End of inner exception stack trace ---
   at System.Runtime.CompilerServices.TaskAwaiter.ThrowForNonSuccess(Task task)
   at System.Runtime.CompilerServices.TaskAwaiter.HandleNonSuccessAndDebuggerNotification(Task task)
   at System.Runtime.CompilerServices.ConfiguredTaskAwaitable`1.ConfiguredTaskAwaiter.GetResult()
   at System.Net.Http.HttpClient.<FinishSendAsync>d__58.MoveNext()
--- End of stack trace from previous location where exception was thrown ---
   at System.Runtime.CompilerServices.TaskAwaiter.ThrowForNonSuccess(Task task)
   at System.Runtime.CompilerServices.TaskAwaiter.HandleNonSuccessAndDebuggerNotification(Task task)
   at EdjCase.JsonRpc.Client.RpcClient.<SendAsync>d__23`2.MoveNext()
   --- End of inner exception stack trace ---
   at EdjCase.JsonRpc.Client.RpcClient.<SendAsync>d__23`2.MoveNext()
--- End of stack trace from previous location where exception was thrown ---
   at System.Runtime.CompilerServices.TaskAwaiter.ThrowForNonSuccess(Task task)
   at System.Runtime.CompilerServices.TaskAwaiter.HandleNonSuccessAndDebuggerNotification(Task task)
   at EdjCase.JsonRpc.Client.RpcClient.<SendRequestAsync>d__20.MoveNext()
--- End of stack trace from previous location where exception was thrown ---
   at System.Runtime.CompilerServices.TaskAwaiter.ThrowForNonSuccess(Task task)
   at System.Runtime.CompilerServices.TaskAwaiter.HandleNonSuccessAndDebuggerNotification(Task task)
   at System.Runtime.CompilerServices.ConfiguredTaskAwaitable`1.ConfiguredTaskAwaiter.GetResult()
   at Nethereum.JsonRpc.Client.RpcRequestResponseHandlerNoParam`1.<SendRequestAsync>d__7.MoveNext()
--- End of stack trace from previous location where exception was thrown ---
   at System.Runtime.CompilerServices.TaskAwaiter.ThrowForNonSuccess(Task task)
   at System.Runtime.CompilerServices.TaskAwaiter.HandleNonSuccessAndDebuggerNotification(Task task)
   at System.Runtime.CompilerServices.TaskAwaiter`1.GetResult()
   at Services.ContractService.<GetCurrentBlock>d__9.MoveNext() in E:\Projects\EthereumApiDotNetCore\src\Services\ContractService.cs:line 179
--- End of stack trace from previous location where exception was thrown ---
   at NUnit.Framework.Internal.ExceptionHelper.Rethrow(Exception exception)
   at NUnit.Framework.Internal.AsyncInvocationRegion.AsyncTaskInvocationRegion.WaitForPendingOperationsToComplete(Object invocationResult)
   at NUnit.Framework.Constraints.ThrowsConstraint.ExceptionInterceptor.Intercept(Object invocation)>
]]></message>
        </failure>
      </test-suite>
      <test-case id="1005" name="TestFirePaymentEvent" fullname="Tests.EthereumQueueOutTests.TestFirePaymentEvent" methodname="TestFirePaymentEvent" classname="Tests.EthereumQueueOutTests" runstate="Runnable" seed="766830854" result="Failed" site="Parent" start-time="0001-01-01 00:00:00Z" end-time="0001-01-01 00:00:00Z" duration="0.000000" asserts="0">
        <failure>
          <message><![CDATA[OneTimeSetUp:   Please, run ethereum node (geth.exe)
  Expected: No Exception to be thrown
  But was:  <EdjCase.JsonRpc.Client.RpcClientUnknownException: Error occurred when trying to send rpc requests(s) ---> System.Net.Http.HttpRequestException: An error occurred while sending the request. ---> System.Net.Http.WinHttpException: Не удается установить соединение с сервером
   at System.Runtime.CompilerServices.TaskAwaiter.ThrowForNonSuccess(Task task)
   at System.Runtime.CompilerServices.TaskAwaiter.HandleNonSuccessAndDebuggerNotification(Task task)
   at System.Runtime.CompilerServices.ConfiguredTaskAwaitable`1.ConfiguredTaskAwaiter.GetResult()
   at System.Net.Http.WinHttpHandler.<StartRequest>d__101.MoveNext()
   --- End of inner exception stack trace ---
   at System.Runtime.CompilerServices.TaskAwaiter.ThrowForNonSuccess(Task task)
   at System.Runtime.CompilerServices.TaskAwaiter.HandleNonSuccessAndDebuggerNotification(Task task)
   at System.Runtime.CompilerServices.ConfiguredTaskAwaitable`1.ConfiguredTaskAwaiter.GetResult()
   at System.Net.Http.HttpClient.<FinishSendAsync>d__58.MoveNext()
--- End of stack trace from previous location where exception was thrown ---
   at System.Runtime.CompilerServices.TaskAwaiter.ThrowForNonSuccess(Task task)
   at System.Runtime.CompilerServices.TaskAwaiter.HandleNonSuccessAndDebuggerNotification(Task task)
   at EdjCase.JsonRpc.Client.RpcClient.<SendAsync>d__23`2.MoveNext()
   --- End of inner exception stack trace ---
   at EdjCase.JsonRpc.Client.RpcClient.<SendAsync>d__23`2.MoveNext()
--- End of stack trace from previous location where exception was thrown ---
   at System.Runtime.CompilerServices.TaskAwaiter.ThrowForNonSuccess(Task task)
   at System.Runtime.CompilerServices.TaskAwaiter.HandleNonSuccessAndDebuggerNotification(Task task)
   at EdjCase.JsonRpc.Client.RpcClient.<SendRequestAsync>d__20.MoveNext()
--- End of stack trace from previous location where exception was thrown ---
   at System.Runtime.CompilerServices.TaskAwaiter.ThrowForNonSuccess(Task task)
   at System.Runtime.CompilerServices.TaskAwaiter.HandleNonSuccessAndDebuggerNotification(Task task)
   at System.Runtime.CompilerServices.ConfiguredTaskAwaitable`1.ConfiguredTaskAwaiter.GetResult()
   at Nethereum.JsonRpc.Client.RpcRequestResponseHandlerNoParam`1.<SendRequestAsync>d__7.MoveNext()
--- End of stack trace from previous location where exception was thrown ---
   at System.Runtime.CompilerServices.TaskAwaiter.ThrowForNonSuccess(Task task)
   at System.Runtime.CompilerServices.TaskAwaiter.HandleNonSuccessAndDebuggerNotification(Task task)
   at System.Runtime.CompilerServices.TaskAwaiter`1.GetResult()
   at Services.ContractService.<GetCurrentBlock>d__9.MoveNext() in E:\Projects\EthereumApiDotNetCore\src\Services\ContractService.cs:line 179
--- End of stack trace from previous location where exception was thrown ---
   at NUnit.Framework.Internal.ExceptionHelper.Rethrow(Exception exception)
   at NUnit.Framework.Internal.AsyncInvocationRegion.AsyncTaskInvocationRegion.WaitForPendingOperationsToComplete(Object invocationResult)
   at NUnit.Framework.Constraints.ThrowsConstraint.ExceptionInterceptor.Intercept(Object invocation)>
]]></message>
        </failure>
      </test-case>
      <test-suite type="TestSuite" id="1023" name="JobTests" fullname="Tests.JobTests" runstate="Runnable" testcasecount="4" result="Failed" site="Parent" start-time="0001-01-01 00:00:00Z" end-time="0001-01-01 00:00:00Z" duration="0.000000" total="0" passed="0" failed="0" inconclusive="0" skipped="0" asserts="0">
        <failure>
          <message><![CDATA[OneTimeSetUp:   Please, run ethereum node (geth.exe)
  Expected: No Exception to be thrown
  But was:  <EdjCase.JsonRpc.Client.RpcClientUnknownException: Error occurred when trying to send rpc requests(s) ---> System.Net.Http.HttpRequestException: An error occurred while sending the request. ---> System.Net.Http.WinHttpException: Не удается установить соединение с сервером
   at System.Runtime.CompilerServices.TaskAwaiter.ThrowForNonSuccess(Task task)
   at System.Runtime.CompilerServices.TaskAwaiter.HandleNonSuccessAndDebuggerNotification(Task task)
   at System.Runtime.CompilerServices.ConfiguredTaskAwaitable`1.ConfiguredTaskAwaiter.GetResult()
   at System.Net.Http.WinHttpHandler.<StartRequest>d__101.MoveNext()
   --- End of inner exception stack trace ---
   at System.Runtime.CompilerServices.TaskAwaiter.ThrowForNonSuccess(Task task)
   at System.Runtime.CompilerServices.TaskAwaiter.HandleNonSuccessAndDebuggerNotification(Task task)
   at System.Runtime.CompilerServices.ConfiguredTaskAwaitable`1.ConfiguredTaskAwaiter.GetResult()
   at System.Net.Http.HttpClient.<FinishSendAsync>d__58.MoveNext()
--- End of stack trace from previous location where exception was thrown ---
   at System.Runtime.CompilerServices.TaskAwaiter.ThrowForNonSuccess(Task task)
   at System.Runtime.CompilerServices.TaskAwaiter.HandleNonSuccessAndDebuggerNotification(Task task)
   at EdjCase.JsonRpc.Client.RpcClient.<SendAsync>d__23`2.MoveNext()
   --- End of inner exception stack trace ---
   at EdjCase.JsonRpc.Client.RpcClient.<SendAsync>d__23`2.MoveNext()
--- End of stack trace from previous location where exception was thrown ---
   at System.Runtime.CompilerServices.TaskAwaiter.ThrowForNonSuccess(Task task)
   at System.Runtime.CompilerServices.TaskAwaiter.HandleNonSuccessAndDebuggerNotification(Task task)
   at EdjCase.JsonRpc.Client.RpcClient.<SendRequestAsync>d__20.MoveNext()
--- End of stack trace from previous location where exception was thrown ---
   at System.Runtime.CompilerServices.TaskAwaiter.ThrowForNonSuccess(Task task)
   at System.Runtime.CompilerServices.TaskAwaiter.HandleNonSuccessAndDebuggerNotification(Task task)
   at System.Runtime.CompilerServices.ConfiguredTaskAwaitable`1.ConfiguredTaskAwaiter.GetResult()
   at Nethereum.JsonRpc.Client.RpcRequestResponseHandlerNoParam`1.<SendRequestAsync>d__7.MoveNext()
--- End of stack trace from previous location where exception was thrown ---
   at System.Runtime.CompilerServices.TaskAwaiter.ThrowForNonSuccess(Task task)
   at System.Runtime.CompilerServices.TaskAwaiter.HandleNonSuccessAndDebuggerNotification(Task task)
   at System.Runtime.CompilerServices.TaskAwaiter`1.GetResult()
   at Services.ContractService.<GetCurrentBlock>d__9.MoveNext() in E:\Projects\EthereumApiDotNetCore\src\Services\ContractService.cs:line 179
--- End of stack trace from previous location where exception was thrown ---
   at NUnit.Framework.Internal.ExceptionHelper.Rethrow(Exception exception)
   at NUnit.Framework.Internal.AsyncInvocationRegion.AsyncTaskInvocationRegion.WaitForPendingOperationsToComplete(Object invocationResult)
   at NUnit.Framework.Constraints.ThrowsConstraint.ExceptionInterceptor.Intercept(Object invocation)>
]]></message>
        </failure>
      </test-suite>
      <test-suite type="TestFixture" id="1013" name="CheckPaymentsToUserContractsJobTests" fullname="Tests.JobTests.CheckPaymentsToUserContractsJobTests" classname="Tests.JobTests.CheckPaymentsToUserContractsJobTests" runstate="Runnable" testcasecount="1" result="Failed" site="Parent" start-time="0001-01-01 00:00:00Z" end-time="0001-01-01 00:00:00Z" duration="0.000000" total="0" passed="0" failed="0" inconclusive="0" skipped="0" asserts="0">
        <failure>
          <message><![CDATA[OneTimeSetUp:   Please, run ethereum node (geth.exe)
  Expected: No Exception to be thrown
  But was:  <EdjCase.JsonRpc.Client.RpcClientUnknownException: Error occurred when trying to send rpc requests(s) ---> System.Net.Http.HttpRequestException: An error occurred while sending the request. ---> System.Net.Http.WinHttpException: Не удается установить соединение с сервером
   at System.Runtime.CompilerServices.TaskAwaiter.ThrowForNonSuccess(Task task)
   at System.Runtime.CompilerServices.TaskAwaiter.HandleNonSuccessAndDebuggerNotification(Task task)
   at System.Runtime.CompilerServices.ConfiguredTaskAwaitable`1.ConfiguredTaskAwaiter.GetResult()
   at System.Net.Http.WinHttpHandler.<StartRequest>d__101.MoveNext()
   --- End of inner exception stack trace ---
   at System.Runtime.CompilerServices.TaskAwaiter.ThrowForNonSuccess(Task task)
   at System.Runtime.CompilerServices.TaskAwaiter.HandleNonSuccessAndDebuggerNotification(Task task)
   at System.Runtime.CompilerServices.ConfiguredTaskAwaitable`1.ConfiguredTaskAwaiter.GetResult()
   at System.Net.Http.HttpClient.<FinishSendAsync>d__58.MoveNext()
--- End of stack trace from previous location where exception was thrown ---
   at System.Runtime.CompilerServices.TaskAwaiter.ThrowForNonSuccess(Task task)
   at System.Runtime.CompilerServices.TaskAwaiter.HandleNonSuccessAndDebuggerNotification(Task task)
   at EdjCase.JsonRpc.Client.RpcClient.<SendAsync>d__23`2.MoveNext()
   --- End of inner exception stack trace ---
   at EdjCase.JsonRpc.Client.RpcClient.<SendAsync>d__23`2.MoveNext()
--- End of stack trace from previous location where exception was thrown ---
   at System.Runtime.CompilerServices.TaskAwaiter.ThrowForNonSuccess(Task task)
   at System.Runtime.CompilerServices.TaskAwaiter.HandleNonSuccessAndDebuggerNotification(Task task)
   at EdjCase.JsonRpc.Client.RpcClient.<SendRequestAsync>d__20.MoveNext()
--- End of stack trace from previous location where exception was thrown ---
   at System.Runtime.CompilerServices.TaskAwaiter.ThrowForNonSuccess(Task task)
   at System.Runtime.CompilerServices.TaskAwaiter.HandleNonSuccessAndDebuggerNotification(Task task)
   at System.Runtime.CompilerServices.ConfiguredTaskAwaitable`1.ConfiguredTaskAwaiter.GetResult()
   at Nethereum.JsonRpc.Client.RpcRequestResponseHandlerNoParam`1.<SendRequestAsync>d__7.MoveNext()
--- End of stack trace from previous location where exception was thrown ---
   at System.Runtime.CompilerServices.TaskAwaiter.ThrowForNonSuccess(Task task)
   at System.Runtime.CompilerServices.TaskAwaiter.HandleNonSuccessAndDebuggerNotification(Task task)
   at System.Runtime.CompilerServices.TaskAwaiter`1.GetResult()
   at Services.ContractService.<GetCurrentBlock>d__9.MoveNext() in E:\Projects\EthereumApiDotNetCore\src\Services\ContractService.cs:line 179
--- End of stack trace from previous location where exception was thrown ---
   at NUnit.Framework.Internal.ExceptionHelper.Rethrow(Exception exception)
   at NUnit.Framework.Internal.AsyncInvocationRegion.AsyncTaskInvocationRegion.WaitForPendingOperationsToComplete(Object invocationResult)
   at NUnit.Framework.Constraints.ThrowsConstraint.ExceptionInterceptor.Intercept(Object invocation)>
]]></message>
        </failure>
      </test-suite>
      <test-case id="1014" name="TestCheckPaymentsToUserContractsJobExecute" fullname="Tests.JobTests.CheckPaymentsToUserContractsJobTests.TestCheckPaymentsToUserContractsJobExecute" methodname="TestCheckPaymentsToUserContractsJobExecute" classname="Tests.JobTests.CheckPaymentsToUserContractsJobTests" runstate="Runnable" seed="1496173455" result="Failed" site="Parent" start-time="0001-01-01 00:00:00Z" end-time="0001-01-01 00:00:00Z" duration="0.000000" asserts="0">
        <failure>
          <message><![CDATA[OneTimeSetUp:   Please, run ethereum node (geth.exe)
  Expected: No Exception to be thrown
  But was:  <EdjCase.JsonRpc.Client.RpcClientUnknownException: Error occurred when trying to send rpc requests(s) ---> System.Net.Http.HttpRequestException: An error occurred while sending the request. ---> System.Net.Http.WinHttpException: Не удается установить соединение с сервером
   at System.Runtime.CompilerServices.TaskAwaiter.ThrowForNonSuccess(Task task)
   at System.Runtime.CompilerServices.TaskAwaiter.HandleNonSuccessAndDebuggerNotification(Task task)
   at System.Runtime.CompilerServices.ConfiguredTaskAwaitable`1.ConfiguredTaskAwaiter.GetResult()
   at System.Net.Http.WinHttpHandler.<StartRequest>d__101.MoveNext()
   --- End of inner exception stack trace ---
   at System.Runtime.CompilerServices.TaskAwaiter.ThrowForNonSuccess(Task task)
   at System.Runtime.CompilerServices.TaskAwaiter.HandleNonSuccessAndDebuggerNotification(Task task)
   at System.Runtime.CompilerServices.ConfiguredTaskAwaitable`1.ConfiguredTaskAwaiter.GetResult()
   at System.Net.Http.HttpClient.<FinishSendAsync>d__58.MoveNext()
--- End of stack trace from previous location where exception was thrown ---
   at System.Runtime.CompilerServices.TaskAwaiter.ThrowForNonSuccess(Task task)
   at System.Runtime.CompilerServices.TaskAwaiter.HandleNonSuccessAndDebuggerNotification(Task task)
   at EdjCase.JsonRpc.Client.RpcClient.<SendAsync>d__23`2.MoveNext()
   --- End of inner exception stack trace ---
   at EdjCase.JsonRpc.Client.RpcClient.<SendAsync>d__23`2.MoveNext()
--- End of stack trace from previous location where exception was thrown ---
   at System.Runtime.CompilerServices.TaskAwaiter.ThrowForNonSuccess(Task task)
   at System.Runtime.CompilerServices.TaskAwaiter.HandleNonSuccessAndDebuggerNotification(Task task)
   at EdjCase.JsonRpc.Client.RpcClient.<SendRequestAsync>d__20.MoveNext()
--- End of stack trace from previous location where exception was thrown ---
   at System.Runtime.CompilerServices.TaskAwaiter.ThrowForNonSuccess(Task task)
   at System.Runtime.CompilerServices.TaskAwaiter.HandleNonSuccessAndDebuggerNotification(Task task)
   at System.Runtime.CompilerServices.ConfiguredTaskAwaitable`1.ConfiguredTaskAwaiter.GetResult()
   at Nethereum.JsonRpc.Client.RpcRequestResponseHandlerNoParam`1.<SendRequestAsync>d__7.MoveNext()
--- End of stack trace from previous location where exception was thrown ---
   at System.Runtime.CompilerServices.TaskAwaiter.ThrowForNonSuccess(Task task)
   at System.Runtime.CompilerServices.TaskAwaiter.HandleNonSuccessAndDebuggerNotification(Task task)
   at System.Runtime.CompilerServices.TaskAwaiter`1.GetResult()
   at Services.ContractService.<GetCurrentBlock>d__9.MoveNext() in E:\Projects\EthereumApiDotNetCore\src\Services\ContractService.cs:line 179
--- End of stack trace from previous location where exception was thrown ---
   at NUnit.Framework.Internal.ExceptionHelper.Rethrow(Exception exception)
   at NUnit.Framework.Internal.AsyncInvocationRegion.AsyncTaskInvocationRegion.WaitForPendingOperationsToComplete(Object invocationResult)
   at NUnit.Framework.Constraints.ThrowsConstraint.ExceptionInterceptor.Intercept(Object invocation)>
]]></message>
        </failure>
      </test-case>
      <test-suite type="TestFixture" id="1017" name="MonitoringJobTests" fullname="Tests.JobTests.MonitoringJobTests" classname="Tests.JobTests.MonitoringJobTests" runstate="Runnable" testcasecount="1" result="Failed" site="Parent" start-time="0001-01-01 00:00:00Z" end-time="0001-01-01 00:00:00Z" duration="0.000000" total="0" passed="0" failed="0" inconclusive="0" skipped="0" asserts="0">
        <failure>
          <message><![CDATA[OneTimeSetUp:   Please, run ethereum node (geth.exe)
  Expected: No Exception to be thrown
  But was:  <EdjCase.JsonRpc.Client.RpcClientUnknownException: Error occurred when trying to send rpc requests(s) ---> System.Net.Http.HttpRequestException: An error occurred while sending the request. ---> System.Net.Http.WinHttpException: Не удается установить соединение с сервером
   at System.Runtime.CompilerServices.TaskAwaiter.ThrowForNonSuccess(Task task)
   at System.Runtime.CompilerServices.TaskAwaiter.HandleNonSuccessAndDebuggerNotification(Task task)
   at System.Runtime.CompilerServices.ConfiguredTaskAwaitable`1.ConfiguredTaskAwaiter.GetResult()
   at System.Net.Http.WinHttpHandler.<StartRequest>d__101.MoveNext()
   --- End of inner exception stack trace ---
   at System.Runtime.CompilerServices.TaskAwaiter.ThrowForNonSuccess(Task task)
   at System.Runtime.CompilerServices.TaskAwaiter.HandleNonSuccessAndDebuggerNotification(Task task)
   at System.Runtime.CompilerServices.ConfiguredTaskAwaitable`1.ConfiguredTaskAwaiter.GetResult()
   at System.Net.Http.HttpClient.<FinishSendAsync>d__58.MoveNext()
--- End of stack trace from previous location where exception was thrown ---
   at System.Runtime.CompilerServices.TaskAwaiter.ThrowForNonSuccess(Task task)
   at System.Runtime.CompilerServices.TaskAwaiter.HandleNonSuccessAndDebuggerNotification(Task task)
   at EdjCase.JsonRpc.Client.RpcClient.<SendAsync>d__23`2.MoveNext()
   --- End of inner exception stack trace ---
   at EdjCase.JsonRpc.Client.RpcClient.<SendAsync>d__23`2.MoveNext()
--- End of stack trace from previous location where exception was thrown ---
   at System.Runtime.CompilerServices.TaskAwaiter.ThrowForNonSuccess(Task task)
   at System.Runtime.CompilerServices.TaskAwaiter.HandleNonSuccessAndDebuggerNotification(Task task)
   at EdjCase.JsonRpc.Client.RpcClient.<SendRequestAsync>d__20.MoveNext()
--- End of stack trace from previous location where exception was thrown ---
   at System.Runtime.CompilerServices.TaskAwaiter.ThrowForNonSuccess(Task task)
   at System.Runtime.CompilerServices.TaskAwaiter.HandleNonSuccessAndDebuggerNotification(Task task)
   at System.Runtime.CompilerServices.ConfiguredTaskAwaitable`1.ConfiguredTaskAwaiter.GetResult()
   at Nethereum.JsonRpc.Client.RpcRequestResponseHandlerNoParam`1.<SendRequestAsync>d__7.MoveNext()
--- End of stack trace from previous location where exception was thrown ---
   at System.Runtime.CompilerServices.TaskAwaiter.ThrowForNonSuccess(Task task)
   at System.Runtime.CompilerServices.TaskAwaiter.HandleNonSuccessAndDebuggerNotification(Task task)
   at System.Runtime.CompilerServices.TaskAwaiter`1.GetResult()
   at Services.ContractService.<GetCurrentBlock>d__9.MoveNext() in E:\Projects\EthereumApiDotNetCore\src\Services\ContractService.cs:line 179
--- End of stack trace from previous location where exception was thrown ---
   at NUnit.Framework.Internal.ExceptionHelper.Rethrow(Exception exception)
   at NUnit.Framework.Internal.AsyncInvocationRegion.AsyncTaskInvocationRegion.WaitForPendingOperationsToComplete(Object invocationResult)
   at NUnit.Framework.Constraints.ThrowsConstraint.ExceptionInterceptor.Intercept(Object invocation)>
]]></message>
        </failure>
      </test-suite>
      <test-case id="1018" name="TestMonitoringJobExecute" fullname="Tests.JobTests.MonitoringJobTests.TestMonitoringJobExecute" methodname="TestMonitoringJobExecute" classname="Tests.JobTests.MonitoringJobTests" runstate="Runnable" seed="1323696227" result="Failed" site="Parent" start-time="0001-01-01 00:00:00Z" end-time="0001-01-01 00:00:00Z" duration="0.000000" asserts="0">
        <failure>
          <message><![CDATA[OneTimeSetUp:   Please, run ethereum node (geth.exe)
  Expected: No Exception to be thrown
  But was:  <EdjCase.JsonRpc.Client.RpcClientUnknownException: Error occurred when trying to send rpc requests(s) ---> System.Net.Http.HttpRequestException: An error occurred while sending the request. ---> System.Net.Http.WinHttpException: Не удается установить соединение с сервером
   at System.Runtime.CompilerServices.TaskAwaiter.ThrowForNonSuccess(Task task)
   at System.Runtime.CompilerServices.TaskAwaiter.HandleNonSuccessAndDebuggerNotification(Task task)
   at System.Runtime.CompilerServices.ConfiguredTaskAwaitable`1.ConfiguredTaskAwaiter.GetResult()
   at System.Net.Http.WinHttpHandler.<StartRequest>d__101.MoveNext()
   --- End of inner exception stack trace ---
   at System.Runtime.CompilerServices.TaskAwaiter.ThrowForNonSuccess(Task task)
   at System.Runtime.CompilerServices.TaskAwaiter.HandleNonSuccessAndDebuggerNotification(Task task)
   at System.Runtime.CompilerServices.ConfiguredTaskAwaitable`1.ConfiguredTaskAwaiter.GetResult()
   at System.Net.Http.HttpClient.<FinishSendAsync>d__58.MoveNext()
--- End of stack trace from previous location where exception was thrown ---
   at System.Runtime.CompilerServices.TaskAwaiter.ThrowForNonSuccess(Task task)
   at System.Runtime.CompilerServices.TaskAwaiter.HandleNonSuccessAndDebuggerNotification(Task task)
   at EdjCase.JsonRpc.Client.RpcClient.<SendAsync>d__23`2.MoveNext()
   --- End of inner exception stack trace ---
   at EdjCase.JsonRpc.Client.RpcClient.<SendAsync>d__23`2.MoveNext()
--- End of stack trace from previous location where exception was thrown ---
   at System.Runtime.CompilerServices.TaskAwaiter.ThrowForNonSuccess(Task task)
   at System.Runtime.CompilerServices.TaskAwaiter.HandleNonSuccessAndDebuggerNotification(Task task)
   at EdjCase.JsonRpc.Client.RpcClient.<SendRequestAsync>d__20.MoveNext()
--- End of stack trace from previous location where exception was thrown ---
   at System.Runtime.CompilerServices.TaskAwaiter.ThrowForNonSuccess(Task task)
   at System.Runtime.CompilerServices.TaskAwaiter.HandleNonSuccessAndDebuggerNotification(Task task)
   at System.Runtime.CompilerServices.ConfiguredTaskAwaitable`1.ConfiguredTaskAwaiter.GetResult()
   at Nethereum.JsonRpc.Client.RpcRequestResponseHandlerNoParam`1.<SendRequestAsync>d__7.MoveNext()
--- End of stack trace from previous location where exception was thrown ---
   at System.Runtime.CompilerServices.TaskAwaiter.ThrowForNonSuccess(Task task)
   at System.Runtime.CompilerServices.TaskAwaiter.HandleNonSuccessAndDebuggerNotification(Task task)
   at System.Runtime.CompilerServices.TaskAwaiter`1.GetResult()
   at Services.ContractService.<GetCurrentBlock>d__9.MoveNext() in E:\Projects\EthereumApiDotNetCore\src\Services\ContractService.cs:line 179
--- End of stack trace from previous location where exception was thrown ---
   at NUnit.Framework.Internal.ExceptionHelper.Rethrow(Exception exception)
   at NUnit.Framework.Internal.AsyncInvocationRegion.AsyncTaskInvocationRegion.WaitForPendingOperationsToComplete(Object invocationResult)
   at NUnit.Framework.Constraints.ThrowsConstraint.ExceptionInterceptor.Intercept(Object invocation)>
]]></message>
        </failure>
      </test-case>
      <test-suite type="TestFixture" id="1015" name="TestMonitoringContractBalanceJob" fullname="Tests.JobTests.TestMonitoringContractBalanceJob" classname="Tests.JobTests.TestMonitoringContractBalanceJob" runstate="Runnable" testcasecount="1" result="Failed" site="Parent" start-time="0001-01-01 00:00:00Z" end-time="0001-01-01 00:00:00Z" duration="0.000000" total="0" passed="0" failed="0" inconclusive="0" skipped="0" asserts="0">
        <failure>
          <message><![CDATA[OneTimeSetUp:   Please, run ethereum node (geth.exe)
  Expected: No Exception to be thrown
  But was:  <EdjCase.JsonRpc.Client.RpcClientUnknownException: Error occurred when trying to send rpc requests(s) ---> System.Net.Http.HttpRequestException: An error occurred while sending the request. ---> System.Net.Http.WinHttpException: Не удается установить соединение с сервером
   at System.Runtime.CompilerServices.TaskAwaiter.ThrowForNonSuccess(Task task)
   at System.Runtime.CompilerServices.TaskAwaiter.HandleNonSuccessAndDebuggerNotification(Task task)
   at System.Runtime.CompilerServices.ConfiguredTaskAwaitable`1.ConfiguredTaskAwaiter.GetResult()
   at System.Net.Http.WinHttpHandler.<StartRequest>d__101.MoveNext()
   --- End of inner exception stack trace ---
   at System.Runtime.CompilerServices.TaskAwaiter.ThrowForNonSuccess(Task task)
   at System.Runtime.CompilerServices.TaskAwaiter.HandleNonSuccessAndDebuggerNotification(Task task)
   at System.Runtime.CompilerServices.ConfiguredTaskAwaitable`1.ConfiguredTaskAwaiter.GetResult()
   at System.Net.Http.HttpClient.<FinishSendAsync>d__58.MoveNext()
--- End of stack trace from previous location where exception was thrown ---
   at System.Runtime.CompilerServices.TaskAwaiter.ThrowForNonSuccess(Task task)
   at System.Runtime.CompilerServices.TaskAwaiter.HandleNonSuccessAndDebuggerNotification(Task task)
   at EdjCase.JsonRpc.Client.RpcClient.<SendAsync>d__23`2.MoveNext()
   --- End of inner exception stack trace ---
   at EdjCase.JsonRpc.Client.RpcClient.<SendAsync>d__23`2.MoveNext()
--- End of stack trace from previous location where exception was thrown ---
   at System.Runtime.CompilerServices.TaskAwaiter.ThrowForNonSuccess(Task task)
   at System.Runtime.CompilerServices.TaskAwaiter.HandleNonSuccessAndDebuggerNotification(Task task)
   at EdjCase.JsonRpc.Client.RpcClient.<SendRequestAsync>d__20.MoveNext()
--- End of stack trace from previous location where exception was thrown ---
   at System.Runtime.CompilerServices.TaskAwaiter.ThrowForNonSuccess(Task task)
   at System.Runtime.CompilerServices.TaskAwaiter.HandleNonSuccessAndDebuggerNotification(Task task)
   at System.Runtime.CompilerServices.ConfiguredTaskAwaitable`1.ConfiguredTaskAwaiter.GetResult()
   at Nethereum.JsonRpc.Client.RpcRequestResponseHandlerNoParam`1.<SendRequestAsync>d__7.MoveNext()
--- End of stack trace from previous location where exception was thrown ---
   at System.Runtime.CompilerServices.TaskAwaiter.ThrowForNonSuccess(Task task)
   at System.Runtime.CompilerServices.TaskAwaiter.HandleNonSuccessAndDebuggerNotification(Task task)
   at System.Runtime.CompilerServices.TaskAwaiter`1.GetResult()
   at Services.ContractService.<GetCurrentBlock>d__9.MoveNext() in E:\Projects\EthereumApiDotNetCore\src\Services\ContractService.cs:line 179
--- End of stack trace from previous location where exception was thrown ---
   at NUnit.Framework.Internal.ExceptionHelper.Rethrow(Exception exception)
   at NUnit.Framework.Internal.AsyncInvocationRegion.AsyncTaskInvocationRegion.WaitForPendingOperationsToComplete(Object invocationResult)
   at NUnit.Framework.Constraints.ThrowsConstraint.ExceptionInterceptor.Intercept(Object invocation)>
]]></message>
        </failure>
      </test-suite>
      <test-case id="1016" name="TestMonitoringContractBalanceJobExecute" fullname="Tests.JobTests.TestMonitoringContractBalanceJob.TestMonitoringContractBalanceJobExecute" methodname="TestMonitoringContractBalanceJobExecute" classname="Tests.JobTests.TestMonitoringContractBalanceJob" runstate="Runnable" seed="1733432322" result="Failed" site="Parent" start-time="0001-01-01 00:00:00Z" end-time="0001-01-01 00:00:00Z" duration="0.000000" asserts="0">
        <failure>
          <message><![CDATA[OneTimeSetUp:   Please, run ethereum node (geth.exe)
  Expected: No Exception to be thrown
  But was:  <EdjCase.JsonRpc.Client.RpcClientUnknownException: Error occurred when trying to send rpc requests(s) ---> System.Net.Http.HttpRequestException: An error occurred while sending the request. ---> System.Net.Http.WinHttpException: Не удается установить соединение с сервером
   at System.Runtime.CompilerServices.TaskAwaiter.ThrowForNonSuccess(Task task)
   at System.Runtime.CompilerServices.TaskAwaiter.HandleNonSuccessAndDebuggerNotification(Task task)
   at System.Runtime.CompilerServices.ConfiguredTaskAwaitable`1.ConfiguredTaskAwaiter.GetResult()
   at System.Net.Http.WinHttpHandler.<StartRequest>d__101.MoveNext()
   --- End of inner exception stack trace ---
   at System.Runtime.CompilerServices.TaskAwaiter.ThrowForNonSuccess(Task task)
   at System.Runtime.CompilerServices.TaskAwaiter.HandleNonSuccessAndDebuggerNotification(Task task)
   at System.Runtime.CompilerServices.ConfiguredTaskAwaitable`1.ConfiguredTaskAwaiter.GetResult()
   at System.Net.Http.HttpClient.<FinishSendAsync>d__58.MoveNext()
--- End of stack trace from previous location where exception was thrown ---
   at System.Runtime.CompilerServices.TaskAwaiter.ThrowForNonSuccess(Task task)
   at System.Runtime.CompilerServices.TaskAwaiter.HandleNonSuccessAndDebuggerNotification(Task task)
   at EdjCase.JsonRpc.Client.RpcClient.<SendAsync>d__23`2.MoveNext()
   --- End of inner exception stack trace ---
   at EdjCase.JsonRpc.Client.RpcClient.<SendAsync>d__23`2.MoveNext()
--- End of stack trace from previous location where exception was thrown ---
   at System.Runtime.CompilerServices.TaskAwaiter.ThrowForNonSuccess(Task task)
   at System.Runtime.CompilerServices.TaskAwaiter.HandleNonSuccessAndDebuggerNotification(Task task)
   at EdjCase.JsonRpc.Client.RpcClient.<SendRequestAsync>d__20.MoveNext()
--- End of stack trace from previous location where exception was thrown ---
   at System.Runtime.CompilerServices.TaskAwaiter.ThrowForNonSuccess(Task task)
   at System.Runtime.CompilerServices.TaskAwaiter.HandleNonSuccessAndDebuggerNotification(Task task)
   at System.Runtime.CompilerServices.ConfiguredTaskAwaitable`1.ConfiguredTaskAwaiter.GetResult()
   at Nethereum.JsonRpc.Client.RpcRequestResponseHandlerNoParam`1.<SendRequestAsync>d__7.MoveNext()
--- End of stack trace from previous location where exception was thrown ---
   at System.Runtime.CompilerServices.TaskAwaiter.ThrowForNonSuccess(Task task)
   at System.Runtime.CompilerServices.TaskAwaiter.HandleNonSuccessAndDebuggerNotification(Task task)
   at System.Runtime.CompilerServices.TaskAwaiter`1.GetResult()
   at Services.ContractService.<GetCurrentBlock>d__9.MoveNext() in E:\Projects\EthereumApiDotNetCore\src\Services\ContractService.cs:line 179
--- End of stack trace from previous location where exception was thrown ---
   at NUnit.Framework.Internal.ExceptionHelper.Rethrow(Exception exception)
   at NUnit.Framework.Internal.AsyncInvocationRegion.AsyncTaskInvocationRegion.WaitForPendingOperationsToComplete(Object invocationResult)
   at NUnit.Framework.Constraints.ThrowsConstraint.ExceptionInterceptor.Intercept(Object invocation)>
]]></message>
        </failure>
      </test-case>
      <test-suite type="TestFixture" id="1019" name="TransferTransactionQueueJobTests" fullname="Tests.JobTests.TransferTransactionQueueJobTests" classname="Tests.JobTests.TransferTransactionQueueJobTests" runstate="Runnable" testcasecount="1" result="Failed" site="Parent" start-time="0001-01-01 00:00:00Z" end-time="0001-01-01 00:00:00Z" duration="0.000000" total="0" passed="0" failed="0" inconclusive="0" skipped="0" asserts="0">
        <failure>
          <message><![CDATA[OneTimeSetUp:   Please, run ethereum node (geth.exe)
  Expected: No Exception to be thrown
  But was:  <EdjCase.JsonRpc.Client.RpcClientUnknownException: Error occurred when trying to send rpc requests(s) ---> System.Net.Http.HttpRequestException: An error occurred while sending the request. ---> System.Net.Http.WinHttpException: Не удается установить соединение с сервером
   at System.Runtime.CompilerServices.TaskAwaiter.ThrowForNonSuccess(Task task)
   at System.Runtime.CompilerServices.TaskAwaiter.HandleNonSuccessAndDebuggerNotification(Task task)
   at System.Runtime.CompilerServices.ConfiguredTaskAwaitable`1.ConfiguredTaskAwaiter.GetResult()
   at System.Net.Http.WinHttpHandler.<StartRequest>d__101.MoveNext()
   --- End of inner exception stack trace ---
   at System.Runtime.CompilerServices.TaskAwaiter.ThrowForNonSuccess(Task task)
   at System.Runtime.CompilerServices.TaskAwaiter.HandleNonSuccessAndDebuggerNotification(Task task)
   at System.Runtime.CompilerServices.ConfiguredTaskAwaitable`1.ConfiguredTaskAwaiter.GetResult()
   at System.Net.Http.HttpClient.<FinishSendAsync>d__58.MoveNext()
--- End of stack trace from previous location where exception was thrown ---
   at System.Runtime.CompilerServices.TaskAwaiter.ThrowForNonSuccess(Task task)
   at System.Runtime.CompilerServices.TaskAwaiter.HandleNonSuccessAndDebuggerNotification(Task task)
   at EdjCase.JsonRpc.Client.RpcClient.<SendAsync>d__23`2.MoveNext()
   --- End of inner exception stack trace ---
   at EdjCase.JsonRpc.Client.RpcClient.<SendAsync>d__23`2.MoveNext()
--- End of stack trace from previous location where exception was thrown ---
   at System.Runtime.CompilerServices.TaskAwaiter.ThrowForNonSuccess(Task task)
   at System.Runtime.CompilerServices.TaskAwaiter.HandleNonSuccessAndDebuggerNotification(Task task)
   at EdjCase.JsonRpc.Client.RpcClient.<SendRequestAsync>d__20.MoveNext()
--- End of stack trace from previous location where exception was thrown ---
   at System.Runtime.CompilerServices.TaskAwaiter.ThrowForNonSuccess(Task task)
   at System.Runtime.CompilerServices.TaskAwaiter.HandleNonSuccessAndDebuggerNotification(Task task)
   at System.Runtime.CompilerServices.ConfiguredTaskAwaitable`1.ConfiguredTaskAwaiter.GetResult()
   at Nethereum.JsonRpc.Client.RpcRequestResponseHandlerNoParam`1.<SendRequestAsync>d__7.MoveNext()
--- End of stack trace from previous location where exception was thrown ---
   at System.Runtime.CompilerServices.TaskAwaiter.ThrowForNonSuccess(Task task)
   at System.Runtime.CompilerServices.TaskAwaiter.HandleNonSuccessAndDebuggerNotification(Task task)
   at System.Runtime.CompilerServices.TaskAwaiter`1.GetResult()
   at Services.ContractService.<GetCurrentBlock>d__9.MoveNext() in E:\Projects\EthereumApiDotNetCore\src\Services\ContractService.cs:line 179
--- End of stack trace from previous location where exception was thrown ---
   at NUnit.Framework.Internal.ExceptionHelper.Rethrow(Exception exception)
   at NUnit.Framework.Internal.AsyncInvocationRegion.AsyncTaskInvocationRegion.WaitForPendingOperationsToComplete(Object invocationResult)
   at NUnit.Framework.Constraints.ThrowsConstraint.ExceptionInterceptor.Intercept(Object invocation)>
]]></message>
        </failure>
      </test-suite>
      <test-case id="1020" name="TestTransferTransactionExecute" fullname="Tests.JobTests.TransferTransactionQueueJobTests.TestTransferTransactionExecute" methodname="TestTransferTransactionExecute" classname="Tests.JobTests.TransferTransactionQueueJobTests" runstate="Runnable" seed="512714099" result="Failed" site="Parent" start-time="0001-01-01 00:00:00Z" end-time="0001-01-01 00:00:00Z" duration="0.000000" asserts="0">
        <failure>
          <message><![CDATA[OneTimeSetUp:   Please, run ethereum node (geth.exe)
  Expected: No Exception to be thrown
  But was:  <EdjCase.JsonRpc.Client.RpcClientUnknownException: Error occurred when trying to send rpc requests(s) ---> System.Net.Http.HttpRequestException: An error occurred while sending the request. ---> System.Net.Http.WinHttpException: Не удается установить соединение с сервером
   at System.Runtime.CompilerServices.TaskAwaiter.ThrowForNonSuccess(Task task)
   at System.Runtime.CompilerServices.TaskAwaiter.HandleNonSuccessAndDebuggerNotification(Task task)
   at System.Runtime.CompilerServices.ConfiguredTaskAwaitable`1.ConfiguredTaskAwaiter.GetResult()
   at System.Net.Http.WinHttpHandler.<StartRequest>d__101.MoveNext()
   --- End of inner exception stack trace ---
   at System.Runtime.CompilerServices.TaskAwaiter.ThrowForNonSuccess(Task task)
   at System.Runtime.CompilerServices.TaskAwaiter.HandleNonSuccessAndDebuggerNotification(Task task)
   at System.Runtime.CompilerServices.ConfiguredTaskAwaitable`1.ConfiguredTaskAwaiter.GetResult()
   at System.Net.Http.HttpClient.<FinishSendAsync>d__58.MoveNext()
--- End of stack trace from previous location where exception was thrown ---
   at System.Runtime.CompilerServices.TaskAwaiter.ThrowForNonSuccess(Task task)
   at System.Runtime.CompilerServices.TaskAwaiter.HandleNonSuccessAndDebuggerNotification(Task task)
   at EdjCase.JsonRpc.Client.RpcClient.<SendAsync>d__23`2.MoveNext()
   --- End of inner exception stack trace ---
   at EdjCase.JsonRpc.Client.RpcClient.<SendAsync>d__23`2.MoveNext()
--- End of stack trace from previous location where exception was thrown ---
   at System.Runtime.CompilerServices.TaskAwaiter.ThrowForNonSuccess(Task task)
   at System.Runtime.CompilerServices.TaskAwaiter.HandleNonSuccessAndDebuggerNotification(Task task)
   at EdjCase.JsonRpc.Client.RpcClient.<SendRequestAsync>d__20.MoveNext()
--- End of stack trace from previous location where exception was thrown ---
   at System.Runtime.CompilerServices.TaskAwaiter.ThrowForNonSuccess(Task task)
   at System.Runtime.CompilerServices.TaskAwaiter.HandleNonSuccessAndDebuggerNotification(Task task)
   at System.Runtime.CompilerServices.ConfiguredTaskAwaitable`1.ConfiguredTaskAwaiter.GetResult()
   at Nethereum.JsonRpc.Client.RpcRequestResponseHandlerNoParam`1.<SendRequestAsync>d__7.MoveNext()
--- End of stack trace from previous location where exception was thrown ---
   at System.Runtime.CompilerServices.TaskAwaiter.ThrowForNonSuccess(Task task)
   at System.Runtime.CompilerServices.TaskAwaiter.HandleNonSuccessAndDebuggerNotification(Task task)
   at System.Runtime.CompilerServices.TaskAwaiter`1.GetResult()
   at Services.ContractService.<GetCurrentBlock>d__9.MoveNext() in E:\Projects\EthereumApiDotNetCore\src\Services\ContractService.cs:line 179
--- End of stack trace from previous location where exception was thrown ---
   at NUnit.Framework.Internal.ExceptionHelper.Rethrow(Exception exception)
   at NUnit.Framework.Internal.AsyncInvocationRegion.AsyncTaskInvocationRegion.WaitForPendingOperationsToComplete(Object invocationResult)
   at NUnit.Framework.Constraints.ThrowsConstraint.ExceptionInterceptor.Intercept(Object invocation)>
]]></message>
        </failure>
      </test-case>
      <test-suite type="TestFixture" id="1006" name="PaymentServiceTests" fullname="Tests.PaymentServiceTests" classname="Tests.PaymentServiceTests" runstate="Runnable" testcasecount="2" result="Failed" site="Parent" start-time="0001-01-01 00:00:00Z" end-time="0001-01-01 00:00:00Z" duration="0.000000" total="0" passed="0" failed="0" inconclusive="0" skipped="0" asserts="0">
        <failure>
          <message><![CDATA[OneTimeSetUp:   Please, run ethereum node (geth.exe)
  Expected: No Exception to be thrown
  But was:  <EdjCase.JsonRpc.Client.RpcClientUnknownException: Error occurred when trying to send rpc requests(s) ---> System.Net.Http.HttpRequestException: An error occurred while sending the request. ---> System.Net.Http.WinHttpException: Не удается установить соединение с сервером
   at System.Runtime.CompilerServices.TaskAwaiter.ThrowForNonSuccess(Task task)
   at System.Runtime.CompilerServices.TaskAwaiter.HandleNonSuccessAndDebuggerNotification(Task task)
   at System.Runtime.CompilerServices.ConfiguredTaskAwaitable`1.ConfiguredTaskAwaiter.GetResult()
   at System.Net.Http.WinHttpHandler.<StartRequest>d__101.MoveNext()
   --- End of inner exception stack trace ---
   at System.Runtime.CompilerServices.TaskAwaiter.ThrowForNonSuccess(Task task)
   at System.Runtime.CompilerServices.TaskAwaiter.HandleNonSuccessAndDebuggerNotification(Task task)
   at System.Runtime.CompilerServices.ConfiguredTaskAwaitable`1.ConfiguredTaskAwaiter.GetResult()
   at System.Net.Http.HttpClient.<FinishSendAsync>d__58.MoveNext()
--- End of stack trace from previous location where exception was thrown ---
   at System.Runtime.CompilerServices.TaskAwaiter.ThrowForNonSuccess(Task task)
   at System.Runtime.CompilerServices.TaskAwaiter.HandleNonSuccessAndDebuggerNotification(Task task)
   at EdjCase.JsonRpc.Client.RpcClient.<SendAsync>d__23`2.MoveNext()
   --- End of inner exception stack trace ---
   at EdjCase.JsonRpc.Client.RpcClient.<SendAsync>d__23`2.MoveNext()
--- End of stack trace from previous location where exception was thrown ---
   at System.Runtime.CompilerServices.TaskAwaiter.ThrowForNonSuccess(Task task)
   at System.Runtime.CompilerServices.TaskAwaiter.HandleNonSuccessAndDebuggerNotification(Task task)
   at EdjCase.JsonRpc.Client.RpcClient.<SendRequestAsync>d__20.MoveNext()
--- End of stack trace from previous location where exception was thrown ---
   at System.Runtime.CompilerServices.TaskAwaiter.ThrowForNonSuccess(Task task)
   at System.Runtime.CompilerServices.TaskAwaiter.HandleNonSuccessAndDebuggerNotification(Task task)
   at System.Runtime.CompilerServices.ConfiguredTaskAwaitable`1.ConfiguredTaskAwaiter.GetResult()
   at Nethereum.JsonRpc.Client.RpcRequestResponseHandlerNoParam`1.<SendRequestAsync>d__7.MoveNext()
--- End of stack trace from previous location where exception was thrown ---
   at System.Runtime.CompilerServices.TaskAwaiter.ThrowForNonSuccess(Task task)
   at System.Runtime.CompilerServices.TaskAwaiter.HandleNonSuccessAndDebuggerNotification(Task task)
   at System.Runtime.CompilerServices.TaskAwaiter`1.GetResult()
   at Services.ContractService.<GetCurrentBlock>d__9.MoveNext() in E:\Projects\EthereumApiDotNetCore\src\Services\ContractService.cs:line 179
--- End of stack trace from previous location where exception was thrown ---
   at NUnit.Framework.Internal.ExceptionHelper.Rethrow(Exception exception)
   at NUnit.Framework.Internal.AsyncInvocationRegion.AsyncTaskInvocationRegion.WaitForPendingOperationsToComplete(Object invocationResult)
   at NUnit.Framework.Constraints.ThrowsConstraint.ExceptionInterceptor.Intercept(Object invocation)>
]]></message>
        </failure>
      </test-suite>
      <test-case id="1007" name="TestGetMainBalance" fullname="Tests.PaymentServiceTests.TestGetMainBalance" methodname="TestGetMainBalance" classname="Tests.PaymentServiceTests" runstate="Runnable" seed="539622899" result="Failed" site="Parent" start-time="0001-01-01 00:00:00Z" end-time="0001-01-01 00:00:00Z" duration="0.000000" asserts="0">
        <failure>
          <message><![CDATA[OneTimeSetUp:   Please, run ethereum node (geth.exe)
  Expected: No Exception to be thrown
  But was:  <EdjCase.JsonRpc.Client.RpcClientUnknownException: Error occurred when trying to send rpc requests(s) ---> System.Net.Http.HttpRequestException: An error occurred while sending the request. ---> System.Net.Http.WinHttpException: Не удается установить соединение с сервером
   at System.Runtime.CompilerServices.TaskAwaiter.ThrowForNonSuccess(Task task)
   at System.Runtime.CompilerServices.TaskAwaiter.HandleNonSuccessAndDebuggerNotification(Task task)
   at System.Runtime.CompilerServices.ConfiguredTaskAwaitable`1.ConfiguredTaskAwaiter.GetResult()
   at System.Net.Http.WinHttpHandler.<StartRequest>d__101.MoveNext()
   --- End of inner exception stack trace ---
   at System.Runtime.CompilerServices.TaskAwaiter.ThrowForNonSuccess(Task task)
   at System.Runtime.CompilerServices.TaskAwaiter.HandleNonSuccessAndDebuggerNotification(Task task)
   at System.Runtime.CompilerServices.ConfiguredTaskAwaitable`1.ConfiguredTaskAwaiter.GetResult()
   at System.Net.Http.HttpClient.<FinishSendAsync>d__58.MoveNext()
--- End of stack trace from previous location where exception was thrown ---
   at System.Runtime.CompilerServices.TaskAwaiter.ThrowForNonSuccess(Task task)
   at System.Runtime.CompilerServices.TaskAwaiter.HandleNonSuccessAndDebuggerNotification(Task task)
   at EdjCase.JsonRpc.Client.RpcClient.<SendAsync>d__23`2.MoveNext()
   --- End of inner exception stack trace ---
   at EdjCase.JsonRpc.Client.RpcClient.<SendAsync>d__23`2.MoveNext()
--- End of stack trace from previous location where exception was thrown ---
   at System.Runtime.CompilerServices.TaskAwaiter.ThrowForNonSuccess(Task task)
   at System.Runtime.CompilerServices.TaskAwaiter.HandleNonSuccessAndDebuggerNotification(Task task)
   at EdjCase.JsonRpc.Client.RpcClient.<SendRequestAsync>d__20.MoveNext()
--- End of stack trace from previous location where exception was thrown ---
   at System.Runtime.CompilerServices.TaskAwaiter.ThrowForNonSuccess(Task task)
   at System.Runtime.CompilerServices.TaskAwaiter.HandleNonSuccessAndDebuggerNotification(Task task)
   at System.Runtime.CompilerServices.ConfiguredTaskAwaitable`1.ConfiguredTaskAwaiter.GetResult()
   at Nethereum.JsonRpc.Client.RpcRequestResponseHandlerNoParam`1.<SendRequestAsync>d__7.MoveNext()
--- End of stack trace from previous location where exception was thrown ---
   at System.Runtime.CompilerServices.TaskAwaiter.ThrowForNonSuccess(Task task)
   at System.Runtime.CompilerServices.TaskAwaiter.HandleNonSuccessAndDebuggerNotification(Task task)
   at System.Runtime.CompilerServices.TaskAwaiter`1.GetResult()
   at Services.ContractService.<GetCurrentBlock>d__9.MoveNext() in E:\Projects\EthereumApiDotNetCore\src\Services\ContractService.cs:line 179
--- End of stack trace from previous location where exception was thrown ---
   at NUnit.Framework.Internal.ExceptionHelper.Rethrow(Exception exception)
   at NUnit.Framework.Internal.AsyncInvocationRegion.AsyncTaskInvocationRegion.WaitForPendingOperationsToComplete(Object invocationResult)
   at NUnit.Framework.Constraints.ThrowsConstraint.ExceptionInterceptor.Intercept(Object invocation)>
]]></message>
        </failure>
      </test-case>
      <test-case id="1008" name="TestTransferFromUserContract" fullname="Tests.PaymentServiceTests.TestTransferFromUserContract" methodname="TestTransferFromUserContract" classname="Tests.PaymentServiceTests" runstate="Runnable" seed="2027233926" result="Failed" site="Parent" start-time="0001-01-01 00:00:00Z" end-time="0001-01-01 00:00:00Z" duration="0.000000" asserts="0">
        <failure>
          <message><![CDATA[OneTimeSetUp:   Please, run ethereum node (geth.exe)
  Expected: No Exception to be thrown
  But was:  <EdjCase.JsonRpc.Client.RpcClientUnknownException: Error occurred when trying to send rpc requests(s) ---> System.Net.Http.HttpRequestException: An error occurred while sending the request. ---> System.Net.Http.WinHttpException: Не удается установить соединение с сервером
   at System.Runtime.CompilerServices.TaskAwaiter.ThrowForNonSuccess(Task task)
   at System.Runtime.CompilerServices.TaskAwaiter.HandleNonSuccessAndDebuggerNotification(Task task)
   at System.Runtime.CompilerServices.ConfiguredTaskAwaitable`1.ConfiguredTaskAwaiter.GetResult()
   at System.Net.Http.WinHttpHandler.<StartRequest>d__101.MoveNext()
   --- End of inner exception stack trace ---
   at System.Runtime.CompilerServices.TaskAwaiter.ThrowForNonSuccess(Task task)
   at System.Runtime.CompilerServices.TaskAwaiter.HandleNonSuccessAndDebuggerNotification(Task task)
   at System.Runtime.CompilerServices.ConfiguredTaskAwaitable`1.ConfiguredTaskAwaiter.GetResult()
   at System.Net.Http.HttpClient.<FinishSendAsync>d__58.MoveNext()
--- End of stack trace from previous location where exception was thrown ---
   at System.Runtime.CompilerServices.TaskAwaiter.ThrowForNonSuccess(Task task)
   at System.Runtime.CompilerServices.TaskAwaiter.HandleNonSuccessAndDebuggerNotification(Task task)
   at EdjCase.JsonRpc.Client.RpcClient.<SendAsync>d__23`2.MoveNext()
   --- End of inner exception stack trace ---
   at EdjCase.JsonRpc.Client.RpcClient.<SendAsync>d__23`2.MoveNext()
--- End of stack trace from previous location where exception was thrown ---
   at System.Runtime.CompilerServices.TaskAwaiter.ThrowForNonSuccess(Task task)
   at System.Runtime.CompilerServices.TaskAwaiter.HandleNonSuccessAndDebuggerNotification(Task task)
   at EdjCase.JsonRpc.Client.RpcClient.<SendRequestAsync>d__20.MoveNext()
--- End of stack trace from previous location where exception was thrown ---
   at System.Runtime.CompilerServices.TaskAwaiter.ThrowForNonSuccess(Task task)
   at System.Runtime.CompilerServices.TaskAwaiter.HandleNonSuccessAndDebuggerNotification(Task task)
   at System.Runtime.CompilerServices.ConfiguredTaskAwaitable`1.ConfiguredTaskAwaiter.GetResult()
   at Nethereum.JsonRpc.Client.RpcRequestResponseHandlerNoParam`1.<SendRequestAsync>d__7.MoveNext()
--- End of stack trace from previous location where exception was thrown ---
   at System.Runtime.CompilerServices.TaskAwaiter.ThrowForNonSuccess(Task task)
   at System.Runtime.CompilerServices.TaskAwaiter.HandleNonSuccessAndDebuggerNotification(Task task)
   at System.Runtime.CompilerServices.TaskAwaiter`1.GetResult()
   at Services.ContractService.<GetCurrentBlock>d__9.MoveNext() in E:\Projects\EthereumApiDotNetCore\src\Services\ContractService.cs:line 179
--- End of stack trace from previous location where exception was thrown ---
   at NUnit.Framework.Internal.ExceptionHelper.Rethrow(Exception exception)
   at NUnit.Framework.Internal.AsyncInvocationRegion.AsyncTaskInvocationRegion.WaitForPendingOperationsToComplete(Object invocationResult)
   at NUnit.Framework.Constraints.ThrowsConstraint.ExceptionInterceptor.Intercept(Object invocation)>
]]></message>
        </failure>
      </test-case>
      <test-suite type="TestFixture" id="1009" name="TestContracts" fullname="Tests.TestContracts" classname="Tests.TestContracts" runstate="Runnable" testcasecount="3" result="Failed" site="Parent" start-time="0001-01-01 00:00:00Z" end-time="0001-01-01 00:00:00Z" duration="0.000000" total="0" passed="0" failed="0" inconclusive="0" skipped="0" asserts="0">
        <failure>
          <message><![CDATA[OneTimeSetUp:   Please, run ethereum node (geth.exe)
  Expected: No Exception to be thrown
  But was:  <EdjCase.JsonRpc.Client.RpcClientUnknownException: Error occurred when trying to send rpc requests(s) ---> System.Net.Http.HttpRequestException: An error occurred while sending the request. ---> System.Net.Http.WinHttpException: Не удается установить соединение с сервером
   at System.Runtime.CompilerServices.TaskAwaiter.ThrowForNonSuccess(Task task)
   at System.Runtime.CompilerServices.TaskAwaiter.HandleNonSuccessAndDebuggerNotification(Task task)
   at System.Runtime.CompilerServices.ConfiguredTaskAwaitable`1.ConfiguredTaskAwaiter.GetResult()
   at System.Net.Http.WinHttpHandler.<StartRequest>d__101.MoveNext()
   --- End of inner exception stack trace ---
   at System.Runtime.CompilerServices.TaskAwaiter.ThrowForNonSuccess(Task task)
   at System.Runtime.CompilerServices.TaskAwaiter.HandleNonSuccessAndDebuggerNotification(Task task)
   at System.Runtime.CompilerServices.ConfiguredTaskAwaitable`1.ConfiguredTaskAwaiter.GetResult()
   at System.Net.Http.HttpClient.<FinishSendAsync>d__58.MoveNext()
--- End of stack trace from previous location where exception was thrown ---
   at System.Runtime.CompilerServices.TaskAwaiter.ThrowForNonSuccess(Task task)
   at System.Runtime.CompilerServices.TaskAwaiter.HandleNonSuccessAndDebuggerNotification(Task task)
   at EdjCase.JsonRpc.Client.RpcClient.<SendAsync>d__23`2.MoveNext()
   --- End of inner exception stack trace ---
   at EdjCase.JsonRpc.Client.RpcClient.<SendAsync>d__23`2.MoveNext()
--- End of stack trace from previous location where exception was thrown ---
   at System.Runtime.CompilerServices.TaskAwaiter.ThrowForNonSuccess(Task task)
   at System.Runtime.CompilerServices.TaskAwaiter.HandleNonSuccessAndDebuggerNotification(Task task)
   at EdjCase.JsonRpc.Client.RpcClient.<SendRequestAsync>d__20.MoveNext()
--- End of stack trace from previous location where exception was thrown ---
   at System.Runtime.CompilerServices.TaskAwaiter.ThrowForNonSuccess(Task task)
   at System.Runtime.CompilerServices.TaskAwaiter.HandleNonSuccessAndDebuggerNotification(Task task)
   at System.Runtime.CompilerServices.ConfiguredTaskAwaitable`1.ConfiguredTaskAwaiter.GetResult()
   at Nethereum.JsonRpc.Client.RpcRequestResponseHandlerNoParam`1.<SendRequestAsync>d__7.MoveNext()
--- End of stack trace from previous location where exception was thrown ---
   at System.Runtime.CompilerServices.TaskAwaiter.ThrowForNonSuccess(Task task)
   at System.Runtime.CompilerServices.TaskAwaiter.HandleNonSuccessAndDebuggerNotification(Task task)
   at System.Runtime.CompilerServices.TaskAwaiter`1.GetResult()
   at Services.ContractService.<GetCurrentBlock>d__9.MoveNext() in E:\Projects\EthereumApiDotNetCore\src\Services\ContractService.cs:line 179
--- End of stack trace from previous location where exception was thrown ---
   at NUnit.Framework.Internal.ExceptionHelper.Rethrow(Exception exception)
   at NUnit.Framework.Internal.AsyncInvocationRegion.AsyncTaskInvocationRegion.WaitForPendingOperationsToComplete(Object invocationResult)
   at NUnit.Framework.Constraints.ThrowsConstraint.ExceptionInterceptor.Intercept(Object invocation)>
]]></message>
        </failure>
      </test-suite>
      <test-case id="1012" name="TestRefillAccount" fullname="Tests.TestContracts.TestRefillAccount" methodname="TestRefillAccount" classname="Tests.TestContracts" runstate="Runnable" seed="2118846775" result="Failed" site="Parent" start-time="0001-01-01 00:00:00Z" end-time="0001-01-01 00:00:00Z" duration="0.000000" asserts="0">
        <failure>
          <message><![CDATA[OneTimeSetUp:   Please, run ethereum node (geth.exe)
  Expected: No Exception to be thrown
  But was:  <EdjCase.JsonRpc.Client.RpcClientUnknownException: Error occurred when trying to send rpc requests(s) ---> System.Net.Http.HttpRequestException: An error occurred while sending the request. ---> System.Net.Http.WinHttpException: Не удается установить соединение с сервером
   at System.Runtime.CompilerServices.TaskAwaiter.ThrowForNonSuccess(Task task)
   at System.Runtime.CompilerServices.TaskAwaiter.HandleNonSuccessAndDebuggerNotification(Task task)
   at System.Runtime.CompilerServices.ConfiguredTaskAwaitable`1.ConfiguredTaskAwaiter.GetResult()
   at System.Net.Http.WinHttpHandler.<StartRequest>d__101.MoveNext()
   --- End of inner exception stack trace ---
   at System.Runtime.CompilerServices.TaskAwaiter.ThrowForNonSuccess(Task task)
   at System.Runtime.CompilerServices.TaskAwaiter.HandleNonSuccessAndDebuggerNotification(Task task)
   at System.Runtime.CompilerServices.ConfiguredTaskAwaitable`1.ConfiguredTaskAwaiter.GetResult()
   at System.Net.Http.HttpClient.<FinishSendAsync>d__58.MoveNext()
--- End of stack trace from previous location where exception was thrown ---
   at System.Runtime.CompilerServices.TaskAwaiter.ThrowForNonSuccess(Task task)
   at System.Runtime.CompilerServices.TaskAwaiter.HandleNonSuccessAndDebuggerNotification(Task task)
   at EdjCase.JsonRpc.Client.RpcClient.<SendAsync>d__23`2.MoveNext()
   --- End of inner exception stack trace ---
   at EdjCase.JsonRpc.Client.RpcClient.<SendAsync>d__23`2.MoveNext()
--- End of stack trace from previous location where exception was thrown ---
   at System.Runtime.CompilerServices.TaskAwaiter.ThrowForNonSuccess(Task task)
   at System.Runtime.CompilerServices.TaskAwaiter.HandleNonSuccessAndDebuggerNotification(Task task)
   at EdjCase.JsonRpc.Client.RpcClient.<SendRequestAsync>d__20.MoveNext()
--- End of stack trace from previous location where exception was thrown ---
   at System.Runtime.CompilerServices.TaskAwaiter.ThrowForNonSuccess(Task task)
   at System.Runtime.CompilerServices.TaskAwaiter.HandleNonSuccessAndDebuggerNotification(Task task)
   at System.Runtime.CompilerServices.ConfiguredTaskAwaitable`1.ConfiguredTaskAwaiter.GetResult()
   at Nethereum.JsonRpc.Client.RpcRequestResponseHandlerNoParam`1.<SendRequestAsync>d__7.MoveNext()
--- End of stack trace from previous location where exception was thrown ---
   at System.Runtime.CompilerServices.TaskAwaiter.ThrowForNonSuccess(Task task)
   at System.Runtime.CompilerServices.TaskAwaiter.HandleNonSuccessAndDebuggerNotification(Task task)
   at System.Runtime.CompilerServices.TaskAwaiter`1.GetResult()
   at Services.ContractService.<GetCurrentBlock>d__9.MoveNext() in E:\Projects\EthereumApiDotNetCore\src\Services\ContractService.cs:line 179
--- End of stack trace from previous location where exception was thrown ---
   at NUnit.Framework.Internal.ExceptionHelper.Rethrow(Exception exception)
   at NUnit.Framework.Internal.AsyncInvocationRegion.AsyncTaskInvocationRegion.WaitForPendingOperationsToComplete(Object invocationResult)
   at NUnit.Framework.Constraints.ThrowsConstraint.ExceptionInterceptor.Intercept(Object invocation)>
]]></message>
        </failure>
      </test-case>
      <test-case id="1010" name="TestUserContractBigAmount" fullname="Tests.TestContracts.TestUserContractBigAmount" methodname="TestUserContractBigAmount" classname="Tests.TestContracts" runstate="Runnable" seed="549414583" result="Failed" site="Parent" start-time="0001-01-01 00:00:00Z" end-time="0001-01-01 00:00:00Z" duration="0.000000" asserts="0">
        <failure>
          <message><![CDATA[OneTimeSetUp:   Please, run ethereum node (geth.exe)
  Expected: No Exception to be thrown
  But was:  <EdjCase.JsonRpc.Client.RpcClientUnknownException: Error occurred when trying to send rpc requests(s) ---> System.Net.Http.HttpRequestException: An error occurred while sending the request. ---> System.Net.Http.WinHttpException: Не удается установить соединение с сервером
   at System.Runtime.CompilerServices.TaskAwaiter.ThrowForNonSuccess(Task task)
   at System.Runtime.CompilerServices.TaskAwaiter.HandleNonSuccessAndDebuggerNotification(Task task)
   at System.Runtime.CompilerServices.ConfiguredTaskAwaitable`1.ConfiguredTaskAwaiter.GetResult()
   at System.Net.Http.WinHttpHandler.<StartRequest>d__101.MoveNext()
   --- End of inner exception stack trace ---
   at System.Runtime.CompilerServices.TaskAwaiter.ThrowForNonSuccess(Task task)
   at System.Runtime.CompilerServices.TaskAwaiter.HandleNonSuccessAndDebuggerNotification(Task task)
   at System.Runtime.CompilerServices.ConfiguredTaskAwaitable`1.ConfiguredTaskAwaiter.GetResult()
   at System.Net.Http.HttpClient.<FinishSendAsync>d__58.MoveNext()
--- End of stack trace from previous location where exception was thrown ---
   at System.Runtime.CompilerServices.TaskAwaiter.ThrowForNonSuccess(Task task)
   at System.Runtime.CompilerServices.TaskAwaiter.HandleNonSuccessAndDebuggerNotification(Task task)
   at EdjCase.JsonRpc.Client.RpcClient.<SendAsync>d__23`2.MoveNext()
   --- End of inner exception stack trace ---
   at EdjCase.JsonRpc.Client.RpcClient.<SendAsync>d__23`2.MoveNext()
--- End of stack trace from previous location where exception was thrown ---
   at System.Runtime.CompilerServices.TaskAwaiter.ThrowForNonSuccess(Task task)
   at System.Runtime.CompilerServices.TaskAwaiter.HandleNonSuccessAndDebuggerNotification(Task task)
   at EdjCase.JsonRpc.Client.RpcClient.<SendRequestAsync>d__20.MoveNext()
--- End of stack trace from previous location where exception was thrown ---
   at System.Runtime.CompilerServices.TaskAwaiter.ThrowForNonSuccess(Task task)
   at System.Runtime.CompilerServices.TaskAwaiter.HandleNonSuccessAndDebuggerNotification(Task task)
   at System.Runtime.CompilerServices.ConfiguredTaskAwaitable`1.ConfiguredTaskAwaiter.GetResult()
   at Nethereum.JsonRpc.Client.RpcRequestResponseHandlerNoParam`1.<SendRequestAsync>d__7.MoveNext()
--- End of stack trace from previous location where exception was thrown ---
   at System.Runtime.CompilerServices.TaskAwaiter.ThrowForNonSuccess(Task task)
   at System.Runtime.CompilerServices.TaskAwaiter.HandleNonSuccessAndDebuggerNotification(Task task)
   at System.Runtime.CompilerServices.TaskAwaiter`1.GetResult()
   at Services.ContractService.<GetCurrentBlock>d__9.MoveNext() in E:\Projects\EthereumApiDotNetCore\src\Services\ContractService.cs:line 179
--- End of stack trace from previous location where exception was thrown ---
   at NUnit.Framework.Internal.ExceptionHelper.Rethrow(Exception exception)
   at NUnit.Framework.Internal.AsyncInvocationRegion.AsyncTaskInvocationRegion.WaitForPendingOperationsToComplete(Object invocationResult)
   at NUnit.Framework.Constraints.ThrowsConstraint.ExceptionInterceptor.Intercept(Object invocation)>
]]></message>
        </failure>
      </test-case>
      <test-case id="1011" name="TestUserContractWrongSender" fullname="Tests.TestContracts.TestUserContractWrongSender" methodname="TestUserContractWrongSender" classname="Tests.TestContracts" runstate="Runnable" seed="1443767791" result="Failed" site="Parent" start-time="0001-01-01 00:00:00Z" end-time="0001-01-01 00:00:00Z" duration="0.000000" asserts="0">
        <failure>
          <message><![CDATA[OneTimeSetUp:   Please, run ethereum node (geth.exe)
  Expected: No Exception to be thrown
  But was:  <EdjCase.JsonRpc.Client.RpcClientUnknownException: Error occurred when trying to send rpc requests(s) ---> System.Net.Http.HttpRequestException: An error occurred while sending the request. ---> System.Net.Http.WinHttpException: Не удается установить соединение с сервером
   at System.Runtime.CompilerServices.TaskAwaiter.ThrowForNonSuccess(Task task)
   at System.Runtime.CompilerServices.TaskAwaiter.HandleNonSuccessAndDebuggerNotification(Task task)
   at System.Runtime.CompilerServices.ConfiguredTaskAwaitable`1.ConfiguredTaskAwaiter.GetResult()
   at System.Net.Http.WinHttpHandler.<StartRequest>d__101.MoveNext()
   --- End of inner exception stack trace ---
   at System.Runtime.CompilerServices.TaskAwaiter.ThrowForNonSuccess(Task task)
   at System.Runtime.CompilerServices.TaskAwaiter.HandleNonSuccessAndDebuggerNotification(Task task)
   at System.Runtime.CompilerServices.ConfiguredTaskAwaitable`1.ConfiguredTaskAwaiter.GetResult()
   at System.Net.Http.HttpClient.<FinishSendAsync>d__58.MoveNext()
--- End of stack trace from previous location where exception was thrown ---
   at System.Runtime.CompilerServices.TaskAwaiter.ThrowForNonSuccess(Task task)
   at System.Runtime.CompilerServices.TaskAwaiter.HandleNonSuccessAndDebuggerNotification(Task task)
   at EdjCase.JsonRpc.Client.RpcClient.<SendAsync>d__23`2.MoveNext()
   --- End of inner exception stack trace ---
   at EdjCase.JsonRpc.Client.RpcClient.<SendAsync>d__23`2.MoveNext()
--- End of stack trace from previous location where exception was thrown ---
   at System.Runtime.CompilerServices.TaskAwaiter.ThrowForNonSuccess(Task task)
   at System.Runtime.CompilerServices.TaskAwaiter.HandleNonSuccessAndDebuggerNotification(Task task)
   at EdjCase.JsonRpc.Client.RpcClient.<SendRequestAsync>d__20.MoveNext()
--- End of stack trace from previous location where exception was thrown ---
   at System.Runtime.CompilerServices.TaskAwaiter.ThrowForNonSuccess(Task task)
   at System.Runtime.CompilerServices.TaskAwaiter.HandleNonSuccessAndDebuggerNotification(Task task)
   at System.Runtime.CompilerServices.ConfiguredTaskAwaitable`1.ConfiguredTaskAwaiter.GetResult()
   at Nethereum.JsonRpc.Client.RpcRequestResponseHandlerNoParam`1.<SendRequestAsync>d__7.MoveNext()
--- End of stack trace from previous location where exception was thrown ---
   at System.Runtime.CompilerServices.TaskAwaiter.ThrowForNonSuccess(Task task)
   at System.Runtime.CompilerServices.TaskAwaiter.HandleNonSuccessAndDebuggerNotification(Task task)
   at System.Runtime.CompilerServices.TaskAwaiter`1.GetResult()
   at Services.ContractService.<GetCurrentBlock>d__9.MoveNext() in E:\Projects\EthereumApiDotNetCore\src\Services\ContractService.cs:line 179
--- End of stack trace from previous location where exception was thrown ---
   at NUnit.Framework.Internal.ExceptionHelper.Rethrow(Exception exception)
   at NUnit.Framework.Internal.AsyncInvocationRegion.AsyncTaskInvocationRegion.WaitForPendingOperationsToComplete(Object invocationResult)
   at NUnit.Framework.Constraints.ThrowsConstraint.ExceptionInterceptor.Intercept(Object invocation)>
]]></message>
        </failure>
      </test-case>
    </test-suite>
  </test-suite>
</test-run>